Traceback (most recent call last):
  File "/opt/hostedtoolcache/Python/3.8.12/x64/lib/python3.8/site-packages/jupyter_cache/executors/utils.py", line 51, in single_nb_execution
    executenb(
  File "/opt/hostedtoolcache/Python/3.8.12/x64/lib/python3.8/site-packages/nbclient/client.py", line 1204, in execute
    return NotebookClient(nb=nb, resources=resources, km=km, **kwargs).execute()
  File "/opt/hostedtoolcache/Python/3.8.12/x64/lib/python3.8/site-packages/nbclient/util.py", line 84, in wrapped
    return just_run(coro(*args, **kwargs))
  File "/opt/hostedtoolcache/Python/3.8.12/x64/lib/python3.8/site-packages/nbclient/util.py", line 62, in just_run
    return loop.run_until_complete(coro)
  File "/opt/hostedtoolcache/Python/3.8.12/x64/lib/python3.8/asyncio/base_events.py", line 616, in run_until_complete
    return future.result()
  File "/opt/hostedtoolcache/Python/3.8.12/x64/lib/python3.8/site-packages/nbclient/client.py", line 663, in async_execute
    await self.async_execute_cell(
  File "/opt/hostedtoolcache/Python/3.8.12/x64/lib/python3.8/site-packages/nbclient/client.py", line 965, in async_execute_cell
    await self._check_raise_for_error(cell, cell_index, exec_reply)
  File "/opt/hostedtoolcache/Python/3.8.12/x64/lib/python3.8/site-packages/nbclient/client.py", line 862, in _check_raise_for_error
    raise CellExecutionError.from_cell_and_msg(cell, exec_reply_content)
nbclient.exceptions.CellExecutionError: An error occurred while executing the following cell:
------------------
import numpy as np
import matplotlib.pyplot as plt
from matplotlib.lines import Line2D
from scipy.stats import norm
from sklearn.metrics import rand_score, adjusted_rand_score, silhouette_score

from utils import proportion
from gibbs_sampler import gibbs, multigibbs_gibbs, data_gen, make_param_dict, pred_label, score

# from matplotlib.pyplot import figure

plt.rcParams["figure.figsize"] = [10,6]
------------------

[0;31m---------------------------------------------------------------------------[0m
[0;31mModuleNotFoundError[0m                       Traceback (most recent call last)
Input [0;32mIn [1][0m, in [0;36m<cell line: 7>[0;34m()[0m
[1;32m      4[0m [38;5;28;01mfrom[39;00m [38;5;21;01mscipy[39;00m[38;5;21;01m.[39;00m[38;5;21;01mstats[39;00m [38;5;28;01mimport[39;00m norm
[1;32m      5[0m [38;5;28;01mfrom[39;00m [38;5;21;01msklearn[39;00m[38;5;21;01m.[39;00m[38;5;21;01mmetrics[39;00m [38;5;28;01mimport[39;00m rand_score, adjusted_rand_score, silhouette_score
[0;32m----> 7[0m [38;5;28;01mfrom[39;00m [38;5;21;01mutils[39;00m [38;5;28;01mimport[39;00m proportion
[1;32m      8[0m [38;5;28;01mfrom[39;00m [38;5;21;01mgibbs_sampler[39;00m [38;5;28;01mimport[39;00m gibbs, multigibbs_gibbs, data_gen, make_param_dict, pred_label, score
[1;32m     10[0m [38;5;66;03m# from matplotlib.pyplot import figure[39;00m

[0;31mModuleNotFoundError[0m: No module named 'utils'
ModuleNotFoundError: No module named 'utils'

